2021-05-16 13:25:32,963 INFO: Microblog startup [in /home/alit/Desktop/Microblog/Micro_blog/app/__init__.py:44]
2021-05-16 13:38:43,641 INFO: Microblog startup [in /home/alit/Desktop/Microblog/Micro_blog/app/__init__.py:44]
2021-05-16 18:20:30,994 INFO: Microblog startup [in /home/alit/Desktop/Microblog/Micro_blog/app/__init__.py:44]
2021-05-17 15:55:17,229 INFO: Microblog startup [in /home/alit/Desktop/Microblog/Micro_blog/app/__init__.py:44]
2021-05-17 15:55:55,680 ERROR: Exception on /index [GET] [in /home/alit/.local/lib/python3.8/site-packages/flask/app.py:1891]
Traceback (most recent call last):
  File "/home/alit/.local/lib/python3.8/site-packages/flask/app.py", line 2447, in wsgi_app
    response = self.full_dispatch_request()
  File "/home/alit/.local/lib/python3.8/site-packages/flask/app.py", line 1952, in full_dispatch_request
    rv = self.handle_user_exception(e)
  File "/home/alit/.local/lib/python3.8/site-packages/flask/app.py", line 1821, in handle_user_exception
    reraise(exc_type, exc_value, tb)
  File "/home/alit/.local/lib/python3.8/site-packages/flask/_compat.py", line 39, in reraise
    raise value
  File "/home/alit/.local/lib/python3.8/site-packages/flask/app.py", line 1950, in full_dispatch_request
    rv = self.dispatch_request()
  File "/home/alit/.local/lib/python3.8/site-packages/flask/app.py", line 1936, in dispatch_request
    return self.view_functions[rule.endpoint](**req.view_args)
  File "/home/alit/.local/lib/python3.8/site-packages/flask_login/utils.py", line 272, in decorated_view
    return func(*args, **kwargs)
  File "/home/alit/Desktop/Microblog/Micro_blog/app/routes.py", line 32, in index
    prev_url = url_for('index',posts.prev_num) \
TypeError: url_for() takes 1 positional argument but 2 were given
2021-05-17 15:56:21,124 ERROR: Exception on /index [GET] [in /home/alit/.local/lib/python3.8/site-packages/flask/app.py:1891]
Traceback (most recent call last):
  File "/home/alit/.local/lib/python3.8/site-packages/flask/app.py", line 2447, in wsgi_app
    response = self.full_dispatch_request()
  File "/home/alit/.local/lib/python3.8/site-packages/flask/app.py", line 1952, in full_dispatch_request
    rv = self.handle_user_exception(e)
  File "/home/alit/.local/lib/python3.8/site-packages/flask/app.py", line 1821, in handle_user_exception
    reraise(exc_type, exc_value, tb)
  File "/home/alit/.local/lib/python3.8/site-packages/flask/_compat.py", line 39, in reraise
    raise value
  File "/home/alit/.local/lib/python3.8/site-packages/flask/app.py", line 1950, in full_dispatch_request
    rv = self.dispatch_request()
  File "/home/alit/.local/lib/python3.8/site-packages/flask/app.py", line 1936, in dispatch_request
    return self.view_functions[rule.endpoint](**req.view_args)
  File "/home/alit/.local/lib/python3.8/site-packages/flask_login/utils.py", line 272, in decorated_view
    return func(*args, **kwargs)
  File "/home/alit/Desktop/Microblog/Micro_blog/app/routes.py", line 32, in index
    prev_url = url_for('index',posts.prev_num) \
TypeError: url_for() takes 1 positional argument but 2 were given
2021-05-17 15:57:29,677 INFO: Microblog startup [in /home/alit/Desktop/Microblog/Micro_blog/app/__init__.py:44]
2021-05-17 16:09:38,747 INFO: Microblog startup [in /home/alit/Desktop/Microblog/Micro_blog/app/__init__.py:44]
2021-05-17 16:16:23,292 INFO: Microblog startup [in /home/alit/Desktop/Microblog/Micro_blog/app/__init__.py:44]
2021-05-18 12:49:24,728 INFO: Microblog startup [in /home/alit/Desktop/Microblog/Micro_blog/app/__init__.py:46]
2021-05-18 12:52:37,504 INFO: Microblog startup [in /home/alit/Desktop/Microblog/Micro_blog/app/__init__.py:46]
2021-05-18 13:01:16,152 INFO: Microblog startup [in /home/alit/Desktop/Microblog/Micro_blog/app/__init__.py:46]
2021-05-18 13:04:58,254 INFO: Microblog startup [in /home/alit/Desktop/Microblog/Micro_blog/app/__init__.py:46]
2021-05-18 13:12:48,712 INFO: Microblog startup [in /home/alit/Desktop/Microblog/Micro_blog/app/__init__.py:46]
2021-05-18 13:24:53,291 INFO: Microblog startup [in /home/alit/Desktop/Microblog/Micro_blog/app/__init__.py:46]
2021-05-18 13:25:35,933 INFO: Microblog startup [in /home/alit/Desktop/Microblog/Micro_blog/app/__init__.py:46]
2021-05-18 13:35:21,302 INFO: Microblog startup [in /home/alit/Desktop/Microblog/Micro_blog/app/__init__.py:46]
2021-05-18 13:37:49,981 INFO: Microblog startup [in /home/alit/Desktop/Microblog/Micro_blog/app/__init__.py:46]
2021-05-18 13:38:37,777 INFO: Microblog startup [in /home/alit/Desktop/Microblog/Micro_blog/app/__init__.py:46]
2021-05-18 13:40:45,095 INFO: Microblog startup [in /home/alit/Desktop/Microblog/Micro_blog/app/__init__.py:46]
2021-05-18 14:34:54,201 INFO: Microblog startup [in /home/alit/Desktop/Microblog/Micro_blog/app/__init__.py:46]
2021-05-18 14:36:19,170 INFO: Microblog startup [in /home/alit/Desktop/Microblog/Micro_blog/app/__init__.py:46]
2021-05-18 14:38:32,357 INFO: Microblog startup [in /home/alit/Desktop/Microblog/Micro_blog/app/__init__.py:45]
2021-05-18 20:55:16,762 INFO: Microblog startup [in /home/alit/Desktop/Microblog/Micro_blog/app/__init__.py:45]
2021-05-18 21:01:39,755 INFO: Microblog startup [in /home/alit/Desktop/Microblog/Micro_blog/app/__init__.py:45]
2021-05-18 21:03:28,835 INFO: Microblog startup [in /home/alit/Desktop/Microblog/Micro_blog/app/__init__.py:45]
2021-05-18 21:04:33,628 ERROR: Exception on /reset_password_request [GET] [in /home/alit/.local/lib/python3.8/site-packages/flask/app.py:1891]
Traceback (most recent call last):
  File "/home/alit/.local/lib/python3.8/site-packages/flask/app.py", line 2447, in wsgi_app
    response = self.full_dispatch_request()
  File "/home/alit/.local/lib/python3.8/site-packages/flask/app.py", line 1952, in full_dispatch_request
    rv = self.handle_user_exception(e)
  File "/home/alit/.local/lib/python3.8/site-packages/flask/app.py", line 1821, in handle_user_exception
    reraise(exc_type, exc_value, tb)
  File "/home/alit/.local/lib/python3.8/site-packages/flask/_compat.py", line 39, in reraise
    raise value
  File "/home/alit/.local/lib/python3.8/site-packages/flask/app.py", line 1950, in full_dispatch_request
    rv = self.dispatch_request()
  File "/home/alit/.local/lib/python3.8/site-packages/flask/app.py", line 1936, in dispatch_request
    return self.view_functions[rule.endpoint](**req.view_args)
  File "/home/alit/Desktop/Microblog/Micro_blog/app/routes.py", line 168, in reset_password_request
    return render_template('reset_password_request.html',
  File "/home/alit/.local/lib/python3.8/site-packages/flask/templating.py", line 138, in render_template
    ctx.app.jinja_env.get_or_select_template(template_name_or_list),
  File "/home/alit/.local/lib/python3.8/site-packages/jinja2/environment.py", line 930, in get_or_select_template
    return self.get_template(template_name_or_list, parent, globals)
  File "/home/alit/.local/lib/python3.8/site-packages/jinja2/environment.py", line 883, in get_template
    return self._load_template(name, self.make_globals(globals))
  File "/home/alit/.local/lib/python3.8/site-packages/jinja2/environment.py", line 857, in _load_template
    template = self.loader.load(self, name, globals)
  File "/home/alit/.local/lib/python3.8/site-packages/jinja2/loaders.py", line 127, in load
    code = environment.compile(source, name, filename)
  File "/home/alit/.local/lib/python3.8/site-packages/jinja2/environment.py", line 638, in compile
    self.handle_exception(source=source_hint)
  File "/home/alit/.local/lib/python3.8/site-packages/jinja2/environment.py", line 832, in handle_exception
    reraise(*rewrite_traceback_stack(source=source))
  File "/home/alit/.local/lib/python3.8/site-packages/jinja2/_compat.py", line 28, in reraise
    raise value.with_traceback(tb)
  File "/home/alit/Desktop/Microblog/Micro_blog/app/templates/reset_password_request.html", line 16, in template
    {% endblock content %}
jinja2.exceptions.TemplateSyntaxError: Encountered unknown tag 'endblock'. You probably made a nesting mistake. Jinja is expecting this tag, but currently looking for 'endfor' or 'else'. The innermost block that needs to be closed is 'for'.
2021-05-18 21:08:43,218 INFO: Microblog startup [in /home/alit/Desktop/Microblog/Micro_blog/app/__init__.py:45]
2021-05-18 21:08:58,222 ERROR: Exception on /reset_password_request [POST] [in /home/alit/.local/lib/python3.8/site-packages/flask/app.py:1891]
Traceback (most recent call last):
  File "/home/alit/.local/lib/python3.8/site-packages/flask/app.py", line 2447, in wsgi_app
    response = self.full_dispatch_request()
  File "/home/alit/.local/lib/python3.8/site-packages/flask/app.py", line 1952, in full_dispatch_request
    rv = self.handle_user_exception(e)
  File "/home/alit/.local/lib/python3.8/site-packages/flask/app.py", line 1821, in handle_user_exception
    reraise(exc_type, exc_value, tb)
  File "/home/alit/.local/lib/python3.8/site-packages/flask/_compat.py", line 39, in reraise
    raise value
  File "/home/alit/.local/lib/python3.8/site-packages/flask/app.py", line 1950, in full_dispatch_request
    rv = self.dispatch_request()
  File "/home/alit/.local/lib/python3.8/site-packages/flask/app.py", line 1936, in dispatch_request
    return self.view_functions[rule.endpoint](**req.view_args)
  File "/home/alit/Desktop/Microblog/Micro_blog/app/routes.py", line 165, in reset_password_request
    send_password_reset_email(user)
  File "/home/alit/Desktop/Microblog/Micro_blog/app/email.py", line 13, in send_password_reset_email
    token = user.get_reset_password_token()
  File "/home/alit/Desktop/Microblog/Micro_blog/app/models.py", line 63, in get_reset_password_token
    {'reset_password': self.id, 'exp': time() + expires_in},
NameError: name 'expires_in' is not defined
2021-05-18 21:11:00,003 INFO: Microblog startup [in /home/alit/Desktop/Microblog/Micro_blog/app/__init__.py:45]
